Workbook

Sheet 표지·범례
A1: 2026 스포츠안전재단 손해구제 서비스 FGI 큐시트 v1.0
A2: 코리아스픽스 숙의공론컨설팅본부 · 작성 2026-09-06 · 근거: 실행계획안 및 진행 시나리오 v0.9.1, 회차별 현장 기록 문서 v0.7
A4: 1. 회차 일정
A5: 그룹 | B5: 일시 | C5: 장소 | D5: 대상 | E5: 큐시트 시트
A6: 그룹 1 · 사업 이용 고객 | B6: 2026-09-07(월) 14:00~16:00 | C6: 패스트파이브 서울역점 (서울 용산구 동자동 56 트윈시티 남산2) | D6: 민간·공공 체육단체, 체육시설 관리자, 선수, 동호인 (6~7명, 2025년 서비스 가입자) | E6: G1_큐시트
A7: 그룹 2 · 사업협력 단체 | B7: 2026-09-08(화) 14:00~16:00 | C7: 스포츠안전재단 교육장 (서울 송파구 올림픽로 424, 올림픽공원 테니스경기장 3층) | D7: 대한체육회, 시도체육회, 종목단체, 대학스포츠, 장애인체육 등 (현장 7명 + 서면 1명) | E7: G2_큐시트
A8: 그룹 3 · 손해구제 전문가 | B8: 2026-09-15(화) 14:00~16:00 | C8: 패스트파이브 삼성1호점 (서울 강남구 테헤란로87길 36 City Airport Tower 24층) | D8: 공제사·손해보험사·브로커·손해사정·학계 (현장 7명 + 서면 2~3명) | E8: G3_큐시트
A9: 그룹 4 · 재단 내부 관계자 | B9: 2026-09-17(목) 14:00~16:00 | C9: 스포츠안전재단 교육장 (서울 송파구 올림픽로 424, 올림픽공원 테니스경기장 3층) | D9: 재단 임직원 — 보임자 4명, 실무자 4명 (안전공제실 등 관련 부서, 개인 명단 미정) | E9: G4_큐시트
A11: 2. 시트 구성 (큐시트 3종)
A12: 시트 | B12: 용도 | C12: 보는 사람 | D12: 비고
A13: 공통_준비운영 | B13: D-3 · D-1 체크리스트, 회차별 날짜, 사후 일정 | C13: PM · 스탭 전원 | D13: 회차마다 반복 사용
A14: G1~G4_큐시트 | B14: 내부용 + 모더레이터용 겸용. 당일 준비(T-180분~) → 도입 → 파트별 질문 원문 → 마무리 → 종료 후 | C14: 모더레이터 · 스크립터 · 오거나이저 · 등록관리 · 기술 | D14: 모더레이터는 G~I열만 보면 된다. 스탭은 J열.
A15: 공유용_요약 | B15: 회차별 파트 시각표만 담은 대외용 | C15: 재단 담당자 · 참관자(시그널앤펄스) | D15: 질문 원문·연락처 없음. 그대로 공유 가능
A17: 3. 사용법 · 범례
A18: 입력 셀 (노란 바탕·파란 글씨) | B18: 각 회차 시트 C4 ‘시작 시각’과 파트 헤더의 소요(분). 나머지 시각은 수식으로 자동 계산된다.
A19: 회색 행 | B19: 당일 준비 (T-180분 ~ T=0). 시작 시각 기준 역산.
A20: 파란 굵은 행 | B20: 파트 헤더. 시작·종료·소요. 스크립터가 K열에 실제 시작 시각을 적는다.
A21: 하늘색 행 | B21: 송출 — 기술 스탭이 인터뷰룸 모니터를 전환하는 시점.
A22: 노란 행 | B22: 거수 — 오거나이저가 인원 수를 기록한다.
A23: 연두 행 | B23: 평가지 — 등록 관리가 배부·회수한다.
A24: 주황 행 | B24: 종료 후 — 파일 저장, 답례, 종료 직후 정리, 철수.
A26: 4. 운영 인력 (회차당 6인)
A27: 역할 | B27: 성명 | C27: 휴대전화 | D27: 담당 업무
A28: PM · 총괄 | B28: 이소연 차장 | D28: 일정·품질 총괄, 안전 대책, 종료 직후 정리 주관
A29: 모더레이터 | D29: 인터뷰룸 진행, 질문, 송출 시점 지시
A30: 스크립터 | D30: 모니터링룸 실시간 기록, 실제 시작 시각, 녹취록 초안
A31: 오거나이저 | D31: 모니터링룸 총괄, 거수 결과 기록, 모더레이터에 시그널
A32: 등록 관리 (2인) | D32: 등록데스크, 동의서·평가지 회수, 답례 지급, 참석 확인 전화
A33: 기술 | D33: 줌 카메라 3대, Plaud 2대, 화면 송출, 인터넷
A34: 참관 (시그널앤펄스 2인) | D34: 모니터링룸 참관
A35: ※ 노란 칸은 회차 확정 시 기입. 현장 기록 문서 v0.7에도 같은 칸이 비어 있다.
A37: 5. 확인 필요 (2026-09-06 기준)
A38: ☐ 사후 서면 의견 제출 채널(이메일·온라인 폼) — 그룹 1 마무리(9/7 15:50) 전 확정
A39: ☐ 그룹 2 예비 10분 배분 — 권장: 개선 제안·협력 확대 25분
A40: ☐ 운영 인력 성함·휴대전화, 비상 연락처(건물 관리실·재단 담당자·인근 병원)
A41: ☐ 그룹 4 참석자 개인 명단 (재단 전달 대기)
A42: ☐ 9/7은 그룹 1 D-day이자 그룹 2 D-1 — 종료 후 그룹 2 참석 확인 전화 1차·리허설 담당 지정

Sheet 공통_준비운영
A1: 공통 준비·운영 일정 (회차마다 반복)
A2: 표준: 코리아스픽스 업무표준 ③단계 3.2 FGD 항목 + 실행계획안 v0.9.1 추진 절차. 날짜는 2026-09-06 기준.
A4: 1. 회차별 날짜
A5: 시점 | B5: 그룹 1 | C5: 그룹 2 | D5: 그룹 3 | E5: 그룹 4 | F5: 비고
A6: D-3 준비 점검 | B6: 9/4(금) | C6: 9/4(금)에 함께 | D6: 9/11(금) | E6: 9/14(월) | F6: 주말이면 직전 금요일
A7: D-1 리허설 · 참석 확인 1차 | B7: 9/6(일) | C7: 9/7(월) 그룹 1 종료 직후 | D7: 9/14(월) | E7: 9/16(수)
A8: D-day | B8: 9/7(월) | C8: 9/8(화) | D8: 9/15(화) | E8: 9/17(목) | F8: 14:00~16:00
A9: D+1 서면 평가지 입력 | B9: 9/8(화) | C9: 9/9(수) | D9: 9/16(수) | E9: 9/18(금)
A10: 사후 서면 의견 마감 (3영업일) | B10: 9/10(목) | C10: 9/11(금) | D10: 9/18(금) | E10: 9/22(화)
A11: 녹취록 완성 (D+10) | B11: 9/17(목) | C11: 9/18(금) | D11: 9/23(수) ※ | E11: 9/23(수) 또는 9/29(화) ※ | F11: ※ 추석 연휴(9/24~9/28 예상) 회피, 재단 협의
A13: 2. D-3 체크리스트
A14: 시점 | B14: 업무 | E14: 담당 | F14: 확인
A15: D-3 | B15: 장소 인터넷(Wi-Fi·유선) 계정·속도·동시 접속 가능 대수 확인 | E15: 기술 | F15: ☐
A16: D-3 | B16: 모니터링룸 책상·의자 = 참관 인원 + 스탭 3인 요청 (재단 교육장은 재단 담당자 경유) | E16: 등록관리 | F16: ☐
A17: D-3 | B17: 모더레이터 사전 브리핑 60분 — 과업 목적·조사 설계·재단 사업 구조·관련 법령 4종·그룹별 질문 의도·송출 자료 | E17: PM | F17: ☐
A18: D-3 | B18: 참석 확정자 안내 문자 2차 (일시·장소·대중교통·주차) | E18: 등록관리 | F18: ☐
A19: D-3 | B19: 서면 평가지·동의서·답례 서류·명패·사후 의견 안내문 인쇄 (인원 + 5부) | E19: 등록관리 | F19: ☐
A20: D-3 | B20: 대체 참석자 Pool 5명 이상 확보 상태 확인, 서면 참여자에게 질문지·평가지 발송 | E20: PM | F20: ☐
A22: 3. D-1 체크리스트
A23: 시점 | B23: 업무 | E23: 담당 | F23: 확인
A24: D-1 | B24: 진행 리허설 — 큐시트 순서대로 스크립트 낭독, 송출 자료 전환, 줌·녹음 동선 | E24: PM | F24: ☐
A25: D-1 | B25: 참석 확인 전화 1차 (R.S.V.P), 불참 시 대체 Pool 즉시 충원 | E25: 등록관리 | F25: ☐
A26: D-1 | B26: 모니터링룸 참관자에게 일시·장소·주차·노트북 지참 안내 | E26: 오거나이저 | F26: ☐
A27: D-1 | B27: 패킹리스트 ‘담음’ 체크 — 서류·명패·노트북 2·줌 카메라 3·Plaud 2·멀티탭·랜선·테더링·다과 | E27: 등록관리 · 기술 | F27: ☐
A28: D-1 | B28: 큐시트·현장 기록 문서에 운영 인력 성함·휴대전화, 비상 연락처 기입, 모더레이터·스크립터용 2부 인쇄 | E28: PM | F28: ☐
A29: D-1 | B29: Plaud 2대·노트북·보조배터리 완충, 송출 자료 오프라인 사본 저장 | E29: 기술 | F29: ☐
A31: 4. 사후 일정
A32: 시점 | B32: 업무 | E32: 담당 | F32: 확인
A33: D+1 | B33: 서면 평가지 입력, 녹화·녹음 파일 백업, 종료 직후 정리 내용 flow 게시 | E33: 등록관리 · PM | F33: ☐
A34: D+3영업일 | B34: 사후 서면 의견 취합 마감 → 출처 표시 후 그룹·주제별 코딩 | E34: PM | F34: ☐
A35: D+10 | B35: 녹취록 완성 — Plaud AI 초안 + 스크립터 교정, 발언별 주제 코드(A~J) 부여 | E35: 스크립터 | F35: ☐
A36: 녹취록 +5일 | B36: 회차 분석 보고서 (Key Findings, 긍·부정 코딩, 정량조사 상이 지점) | E36: 연구원 | F36: ☐
A37: D+7 ~ D+14 | B37: 참석자 답례비·스탭 급여·장소 대관 정산 | E37: 연구원 | F37: ☐
A38: 10/12(월) 목표 | B38: 종합 보고서 초안 (재단 납기 확정 시 갱신) | E38: PM | F38: ☐

Sheet G1_큐시트
A1: [그룹 1 · 사업 이용 고객] 스포츠안전재단 손해구제 서비스 FGI 큐시트
A2: 2026-09-07(월) · 패스트파이브 서울역점 (서울 용산구 동자동 56 트윈시티 남산2)
A3: 대상: 민간·공공 체육단체, 체육시설 관리자, 선수, 동호인 (6~7명, 2025년 서비스 가입자)
A4: 시작 시각 | C4: 14:00 | D4: ← 실제 시작이 늦어지면 이 셀만 수정 (전체 시각 자동 재계산)
A5: 도입 브리핑 | C5: 사업명 변경 안내만 (특장점 브리핑 없음)
A6: 송출 자료 | C6: 가입 화면 · AI 상담 화면 · 법령 안내 슬라이드 · 법령 슬라이드: https://docs.google.com/presentation/d/1qNKAob6CdE12D9baQVkZxUtktVQAWlEgfi2QJ_5gaso/edit
A8: No. | B8: 시작 | C8: 종료 | D8: 소요(분) | E8: 파트 | F8: 구분 | G8: 진행 내용 (모더레이터 멘트 · 질문 원문) | H8: 송출 · 자료 | I8: 담당 | J8: 스탭 액션 (모니터링룸 · 등록 · 기술) | K8: 실제 시각 · 기록
A9: 1 | B9: =$C$4-180/1440 -> 0.45833333 | D9: T-180분 | E9: 당일 준비 | F9: 참석 확인 | G9: 참석 확인 전화 2차 — 불참 발생 시 대체 Pool에서 즉시 충원, 좌석·명패 재조정 | I9: 등록관리
A10: 2 | B10: =$C$4-90/1440 -> 0.52083333 | D10: T-90분 | E10: 당일 준비 | F10: 집결 | G10: 스탭 현장 집결·입실 (대관 장소는 예약 시작 시각 확인). 비상구·소화기·대피로 확인 | I10: 전원 · 기술
A11: 3 | B11: =$C$4-80/1440 -> 0.52777778 | D11: T-80분 | E11: 당일 준비 | F11: 현장 미팅 | G11: 역할·동선·비상 연락처·오늘 회차 특이사항(참석 인원, 서면 참여자, 참관자) 공유 | I11: PM
A12: 4 | B12: =$C$4-60/1440 -> 0.54166667 | D12: T-60분 | E12: 당일 준비 | F12: 세팅 | G12: 인터뷰룸 좌석(원형·ㄷ자)·탁상 명패(P번호)·좌석배치표 배치 / 음료·종이컵·냅킨(여분 10%) / 모니터링룸 책상·의자·좌석별 전원 | I12: 등록관리
A13: 5 | B13: =$C$4-45/1440 -> 0.55208333 | D13: T-45분 | E13: 당일 준비 | F13: 기술 | G13: 줌 카메라 3대 연결, 모니터링룸 화면·음향 확인 / 두 방 인터넷 속도 확인(끊기면 테더링) / 노트북별 전원·인터넷·현장 기록 문서 접속 / Plaud 2대 충전·녹음 대기 | I13: 기술
A14: 6 | B14: =$C$4-30/1440 -> 0.5625 | D14: T-30분 | E14: 당일 준비 | F14: 송출 준비 | G14: 송출 자료 순서대로 탭 열기 · 현장 기록 문서를 모더레이터 노트북에 열람 상태로 · 현장 리허설 1회전(송출 전환, 모니터링룸 화면·음향) | I14: 기술
A15: 7 | B15: =$C$4-20/1440 -> 0.56944444 | D15: T-20분 | E15: 당일 준비 | F15: 리마인드 | G15: 모더레이터 리마인드 — 첫 5분 진행 순서와 송출 시점 재확인. 참관자 착석·개인정보 원칙(번호 사용·촬영 금지) 안내 | I15: PM · 오거나이저
A16: 8 | B16: =$C$4-10/1440 -> 0.57638889 | D16: T-10분 | E16: 당일 준비 | F16: 등록 | G16: 등록 개시 — 인적 사항 확인, 명패 배부·좌석 안내, 녹음·녹화 동의서 서명, 사전 서면 평가지 배부·회수, 답례 지급 정보 서류 수령 | I16: 등록관리
A17: 9 | B17: =$C$4 -> 14:00 | D17: T=0 | E17: 당일 준비 | F17: 시작 | G17: 녹화·녹음 개시 — 줌 녹화 + Plaud 2대, 2인 육안 확인. 지각자는 시작 후 10분까지 입장 허용 | I17: 기술 · 등록관리
A18: 10 | B18: =$C$4 -> 14:00 | C18: =B18+D18/1440 -> 0.59027778 | D18: 10 | E18: 도입 | F18: 파트 | G18: ▶ 도입 (10분) | J18: 스크립터: 실제 시작 시각 기입 · 오거나이저: 예정 종료 5분 전 모더레이터에 시그널
A19: 11 | F19: 안내 | G19: 인사 — 오늘 참석해 주셔서 감사합니다. 지금부터 스포츠안전재단 손해구제 서비스 집단심층면접을 시작하겠습니다. | I19: 모더레이터
A20: 12 | F20: 소개 | G20: 모더레이터 소개 — 진행을 맡은 (소속·성명)입니다. 오늘은 정답을 찾는 자리가 아니라 여러분의 경험과 의견을 듣는 자리입니다. | I20: 모더레이터
A21: 13 | F21: 소개 | G21: 조사기관 소개 — 이 조사는 재단과 별개의 제3기관인 코리아스픽스가 수행합니다. | I21: 모더레이터
A22: 14 | F22: 확인 | G22: 참석자 확인 — 명패의 응답자 번호를 확인해 주십시오. 오늘은 성명 대신 번호로 부르겠습니다. | H22: 탁상 명패(P번호) | I22: 모더레이터 | J22: 등록관리: 미서명자 즉시 확인
A23: 15 | F23: 확인 | G23: 녹화·녹음 동의서 서명과 사전 서면 평가지 회수 여부를 확인한다. | H23: 동의서 · 사전 서면 평가지 | I23: 등록관리 | J23: 등록관리: 미서명자 즉시 확인
A24: 16 | F24: 안내 | G24: 진행 안내 — 120분간 쉬는 시간 없이 진행합니다. 화장실은 필요하실 때 다녀오셔도 됩니다. | I24: 모더레이터
A25: 17 | F25: 안내 | G25: 비밀보장 — 발언은 분석 목적으로만 쓰며 보고서에는 성명 없이 인용됩니다. 답변을 원하지 않으시면 넘어가셔도 됩니다. 중도 퇴장도 가능합니다. | I25: 모더레이터
A26: 18 | F26: 안내 | G26: 발언 규칙 — 서로 다른 의견이 그대로 나오는 것이 좋습니다. 한 분씩 말씀해 주시고 다른 분 의견을 반박하지 않으셔도 됩니다. | I26: 모더레이터
A27: 19 | F27: 소개 | G27: 참석자 자기소개 — 번호 순서로 소속과 재단 서비스 이용 경험을 한 줄씩 말씀해 주십시오. | I27: 모더레이터
A28: 20 | F28: 안내 | G28: 사업명 변경 안내 — 재단 사업명이 기존 ‘공제 서비스’에서 ‘손해구제 서비스’로 변경되었습니다. 기존 ‘스포츠안전공제’가 보험 중심의 다소 한정적인 의미였다면, ‘손해구제 서비스’는 스포츠 활동 중 사고 발생 전·중·후 체육인에게 발생할 수 있는 다양한 손해를 폭넓게 구제한다는 의미입니다. 기존 공제보험도 손해구제 서비스에 포함되며, 오늘 논의의 주요 대상은 기존 공제보험입니다. | I28: 모더레이터
A29: 21 | B29: =B18+D18/1440 -> 0.59027778 | C29: =B29+D29/1440 -> 0.59722222 | D29: 10 | E29: 인지·가입 경로 | F29: 파트 | G29: ▶ 인지·가입 경로 (10분) | J29: 스크립터: 실제 시작 시각 기입 · 오거나이저: 예정 종료 5분 전 모더레이터에 시그널
A30: 22 | F30: 질문 | G30: 손해구제 서비스 도입 경로와 첫인상은 어떠했습니까? ① 소속 단체·협회/행사 주최 측 안내 ② 재단 홈페이지·SNS ③ 인터넷 검색 ④ 체육시설·지도자 안내 ⑤ 지인 추천 ⑥ 기타 | I30: 모더레이터
A31: 23 | F31: 거수 | G31: 〔도입 경로〕 ①~⑥ → 인원 | I31: 오거나이저 | J31: 오거나이저: 인원 수 기록 → 스크립터 공유
A32: 24 | F32: 질문 | G32: 가입 전 민간 보험사 상품과 비교해 보셨습니까? (비교한 경우) 재단 상품을 선택한 결정적 이유는 무엇입니까? | I32: 모더레이터
A33: 25 | F33: 질문 | G33: 도입 채널과 그 채널을 선택한 이유는 무엇입니까? ① 온라인 직접 가입 ② 소속 단체 일괄 가입 ③ 전화·오프라인 가입 | I33: 모더레이터
A34: 26 | B34: =B29+D29/1440 -> 0.59722222 | C34: =B34+D34/1440 -> 0.60763889 | D34: 15 | E34: 가입 절차 (정량 A 연동) | F34: 파트 | G34: ▶ 가입 절차 (정량 A 연동) (15분) | J34: 스크립터: 실제 시작 시각 기입 · 오거나이저: 예정 종료 5분 전 모더레이터에 시그널
A35: 27 | F35: 질문 | G35: 가입 절차는 전반적으로 어땠습니까? (간편 / 보통 / 번거로웠다) | I35: 모더레이터
A36: 28 | F36: 질문 | G36: 무심사 가입(병력·부상 이력 무관)의 편의성을 실제로 체감하셨습니까? | I36: 모더레이터
A37: 29 | F37: 질문 | G37: 가입 과정에서 중단하고 싶었거나 불편했던 순간이 있었습니까? — 구체적 에피소드로 청취 | I37: 모더레이터
A38: 30 | F38: 송출 | G38: 인터뷰룸 모니터에 재단 홈페이지 가입 화면을 띄운다. | H38: 재단 홈페이지 가입 화면 | I38: 기술 | J38: 기술: 인터뷰룸 모니터 전환
A39: 31 | F39: 질문 | G39: 온라인(모바일) 가입 화면과 소요시간은 적절했습니까? | I39: 모더레이터
A40: 32 | F40: 송출 | G40: 인터뷰룸 모니터에 AI 상담 화면을 띄운다. | H40: AI 상담 화면 | I40: 기술 | J40: 기술: 인터뷰룸 모니터 전환
A41: 33 | F41: 질문 | G41: AI 상담 서비스를 이용해 보셨습니까? 경험은 어땠습니까? | I41: 모더레이터
...

Sheet G2_큐시트
A1: [그룹 2 · 사업협력 단체] 스포츠안전재단 손해구제 서비스 FGI 큐시트
A2: 2026-09-08(화) · 스포츠안전재단 교육장 (서울 송파구 올림픽로 424, 올림픽공원 테니스경기장 3층)
A3: 대상: 대한체육회, 시도체육회, 종목단체, 대학스포츠, 장애인체육 등 (현장 7명 + 서면 1명)
A4: 시작 시각 | C4: 14:00 | D4: ← 실제 시작이 늦어지면 이 셀만 수정 (전체 시각 자동 재계산)
A5: 도입 브리핑 | C5: 사업명 변경 안내 + 재단 서비스 특장점 3가지 슬라이드(약 5분) → 직후 G2-10·11 평가지 작성·회수
A6: 송출 자료 | C6: 특장점 3가지 슬라이드 · 법령 안내 슬라이드 · 법령 슬라이드: https://docs.google.com/presentation/d/1qNKAob6CdE12D9baQVkZxUtktVQAWlEgfi2QJ_5gaso/edit
A8: No. | B8: 시작 | C8: 종료 | D8: 소요(분) | E8: 파트 | F8: 구분 | G8: 진행 내용 (모더레이터 멘트 · 질문 원문) | H8: 송출 · 자료 | I8: 담당 | J8: 스탭 액션 (모니터링룸 · 등록 · 기술) | K8: 실제 시각 · 기록
A9: 1 | B9: =$C$4-180/1440 -> 0.45833333 | D9: T-180분 | E9: 당일 준비 | F9: 참석 확인 | G9: 참석 확인 전화 2차 — 불참 발생 시 대체 Pool에서 즉시 충원, 좌석·명패 재조정 | I9: 등록관리
A10: 2 | B10: =$C$4-90/1440 -> 0.52083333 | D10: T-90분 | E10: 당일 준비 | F10: 집결 | G10: 스탭 현장 집결·입실 (대관 장소는 예약 시작 시각 확인). 비상구·소화기·대피로 확인 | I10: 전원 · 기술
A11: 3 | B11: =$C$4-80/1440 -> 0.52777778 | D11: T-80분 | E11: 당일 준비 | F11: 현장 미팅 | G11: 역할·동선·비상 연락처·오늘 회차 특이사항(참석 인원, 서면 참여자, 참관자) 공유 | I11: PM
A12: 4 | B12: =$C$4-60/1440 -> 0.54166667 | D12: T-60분 | E12: 당일 준비 | F12: 세팅 | G12: 인터뷰룸 좌석(원형·ㄷ자)·탁상 명패(P번호)·좌석배치표 배치 / 음료·종이컵·냅킨(여분 10%) / 모니터링룸 책상·의자·좌석별 전원 | I12: 등록관리
A13: 5 | B13: =$C$4-45/1440 -> 0.55208333 | D13: T-45분 | E13: 당일 준비 | F13: 기술 | G13: 줌 카메라 3대 연결, 모니터링룸 화면·음향 확인 / 두 방 인터넷 속도 확인(끊기면 테더링) / 노트북별 전원·인터넷·현장 기록 문서 접속 / Plaud 2대 충전·녹음 대기 | I13: 기술
A14: 6 | B14: =$C$4-30/1440 -> 0.5625 | D14: T-30분 | E14: 당일 준비 | F14: 송출 준비 | G14: 송출 자료 순서대로 탭 열기 · 현장 기록 문서를 모더레이터 노트북에 열람 상태로 · 현장 리허설 1회전(송출 전환, 모니터링룸 화면·음향) | I14: 기술
A15: 7 | B15: =$C$4-20/1440 -> 0.56944444 | D15: T-20분 | E15: 당일 준비 | F15: 리마인드 | G15: 모더레이터 리마인드 — 첫 5분 진행 순서와 송출 시점 재확인. 참관자 착석·개인정보 원칙(번호 사용·촬영 금지) 안내 | I15: PM · 오거나이저
A16: 8 | B16: =$C$4-10/1440 -> 0.57638889 | D16: T-10분 | E16: 당일 준비 | F16: 등록 | G16: 등록 개시 — 인적 사항 확인, 명패 배부·좌석 안내, 녹음·녹화 동의서 서명, 사전 서면 평가지 배부·회수, 답례 지급 정보 서류 수령 | I16: 등록관리
A17: 9 | B17: =$C$4 -> 14:00 | D17: T=0 | E17: 당일 준비 | F17: 시작 | G17: 녹화·녹음 개시 — 줌 녹화 + Plaud 2대, 2인 육안 확인. 지각자는 시작 후 10분까지 입장 허용 | I17: 기술 · 등록관리
A18: 10 | B18: =$C$4 -> 14:00 | C18: =B18+D18/1440 -> 0.59027778 | D18: 10 | E18: 도입 | F18: 파트 | G18: ▶ 도입 (10분) | J18: 스크립터: 실제 시작 시각 기입 · 오거나이저: 예정 종료 5분 전 모더레이터에 시그널
A19: 11 | F19: 안내 | G19: 인사 — 오늘 참석해 주셔서 감사합니다. 지금부터 스포츠안전재단 손해구제 서비스 집단심층면접을 시작하겠습니다. | I19: 모더레이터
A20: 12 | F20: 소개 | G20: 모더레이터 소개 — 진행을 맡은 (소속·성명)입니다. 오늘은 정답을 찾는 자리가 아니라 여러분의 경험과 의견을 듣는 자리입니다. | I20: 모더레이터
A21: 13 | F21: 소개 | G21: 조사기관 소개 — 이 조사는 재단과 별개의 제3기관인 코리아스픽스가 수행합니다. | I21: 모더레이터
A22: 14 | F22: 확인 | G22: 참석자 확인 — 명패의 응답자 번호를 확인해 주십시오. 오늘은 성명 대신 번호로 부르겠습니다. | H22: 탁상 명패(P번호) | I22: 모더레이터 | J22: 등록관리: 미서명자 즉시 확인
A23: 15 | F23: 확인 | G23: 녹화·녹음 동의서 서명과 사전 서면 평가지 회수 여부를 확인한다. | H23: 동의서 · 사전 서면 평가지 | I23: 등록관리 | J23: 등록관리: 미서명자 즉시 확인
A24: 16 | F24: 안내 | G24: 진행 안내 — 120분간 쉬는 시간 없이 진행합니다. 화장실은 필요하실 때 다녀오셔도 됩니다. | I24: 모더레이터
A25: 17 | F25: 안내 | G25: 비밀보장 — 발언은 분석 목적으로만 쓰며 보고서에는 성명 없이 인용됩니다. 답변을 원하지 않으시면 넘어가셔도 됩니다. 중도 퇴장도 가능합니다. | I25: 모더레이터
A26: 18 | F26: 안내 | G26: 발언 규칙 — 서로 다른 의견이 그대로 나오는 것이 좋습니다. 한 분씩 말씀해 주시고 다른 분 의견을 반박하지 않으셔도 됩니다. | I26: 모더레이터
A27: 19 | F27: 소개 | G27: 참석자 자기소개 — 번호 순서로 소속과 재단 서비스 이용 경험을 한 줄씩 말씀해 주십시오. | I27: 모더레이터
A28: 20 | F28: 안내 | G28: 사업명 변경 안내 — 재단 사업명이 기존 ‘공제 서비스’에서 ‘손해구제 서비스’로 변경되었습니다. 기존 ‘스포츠안전공제’가 보험 중심의 다소 한정적인 의미였다면, ‘손해구제 서비스’는 스포츠 활동 중 사고 발생 전·중·후 체육인에게 발생할 수 있는 다양한 손해를 폭넓게 구제한다는 의미입니다. 기존 공제보험도 손해구제 서비스에 포함되며, 오늘 논의의 주요 대상은 기존 공제보험입니다. | I28: 모더레이터
A29: 21 | F29: 송출 | G29: 재단 서비스 특장점 브리핑(약 5분) — ① 종목·연령·장애 여부·병력 유무 등에 따른 가입 거절 없음 ② 개인 실손보험 등과 중복 보상 가능(배상책임·실비 담보는 비례보상) ③ 생활체육인·전문체육인 전용·특화 담보 운영(주최 측 과실이 없는 운동 중 부상 치료비, 배상책임 등) | H29: 특장점 3가지 슬라이드 | I29: 모더레이터 | J29: 기술: 인터뷰룸 모니터 전환
A30: 22 | F30: 평가지 | G30: 특장점 브리핑 직후 G2-10·11 평가지 작성·회수 (브리핑 전 작성한 응답은 수정하지 않음) | H30: 서면 평가지 G2-10·11 | I30: 등록관리 | J30: 등록관리: 배부·회수 후 봉투 보관
A31: 23 | B31: =B18+D18/1440 -> 0.59027778 | C31: =B31+D31/1440 -> 0.60416667 | D31: 20 | E31: 협업 경험 | F31: 파트 | G31: ▶ 협업 경험 (20분) | J31: 스크립터: 실제 시작 시각 기입 · 오거나이저: 예정 종료 5분 전 모더레이터에 시그널
A32: 24 | F32: 질문 | G32: 재단과의 업무 협조는 어떤 방식으로 이루어지고 있습니까? | I32: 모더레이터
A33: 25 | F33: 질문 | G33: 재단과의 협업에 전반적으로 만족하십니까? (만족 / 보통 / 아쉽다) 만족스러운 부분과 아쉬운 부분은 각각 무엇입니까? | I33: 모더레이터
A34: 26 | F34: 거수 | G34: 〔협업 만족〕 만족 / 보통 / 아쉽다 → 인원 | I34: 오거나이저 | J34: 오거나이저: 인원 수 기록 → 스크립터 공유
A35: 27 | F35: 질문 | G35: 정보 공유 체계(데이터·현황·정책 방향)를 어떻게 평가하십니까? | I35: 모더레이터
A36: 28 | F36: 질문 | G36: 협력 단체 입장에서 바라보는 재단 서비스의 역할과 한계는 무엇입니까? | I36: 모더레이터
A37: 29 | F37: 질문 | G37: 위 특장점 중 협력단체와 현장 이용자에게 가장 실질적인 가치는 무엇이며, 기대와 실제 운영 사이 차이는 무엇입니까? | I37: 모더레이터
A38: 30 | B38: =B31+D31/1440 -> 0.60416667 | C38: =B38+D38/1440 -> 0.61805556 | D38: 20 | E38: 제도 연계 | F38: 파트 | G38: ▶ 제도 연계 (20분) | J38: 스크립터: 실제 시작 시각 기입 · 오거나이저: 예정 종료 5분 전 모더레이터에 시그널
A39: 31 | F39: 송출 | G39: 인터뷰룸 모니터에 법령 안내 슬라이드 6장을 띄운다. 인지 확인(거수) → 슬라이드 송출 → 경험·의견 청취 순. 사실 전달에 한정하고 법령 해석 요구 시 재단 고객상담(1899-0547) 안내. | H39: 법령 안내 슬라이드 (https://docs.google.com/presentation/d/1qNKAob6CdE12D9baQVkZxUtktVQAWlEgfi2QJ_5gaso/edit) | I39: 기술 | J39: 기술: 인터뷰룸 모니터 전환
A40: 32 | F40: 질문 | G40: 보험·공제 가입과 안전책임 관련 제도가 현장 업무에 미치는 영향과 이행상 애로는 무엇입니까? (복수 선택) ① 대상 파악·관리의 어려움 ② 예산 부담 ③ 행정 절차의 복잡함 ④ 현장(회원)의 인식 부족 ⑤ 안내자료·지원 부족 | I40: 모더레이터
A41: 33 | F41: 거수 | G41: 〔의무 이행 애로 (복수, 2개까지)〕 ①~⑤ → 인원 | I41: 오거나이저 | J41: 오거나이저: 인원 수 기록 → 스크립터 공유
...

Sheet G3_큐시트
A1: [그룹 3 · 손해구제 전문가] 스포츠안전재단 손해구제 서비스 FGI 큐시트
A2: 2026-09-15(화) · 패스트파이브 삼성1호점 (서울 강남구 테헤란로87길 36 City Airport Tower 24층)
A3: 대상: 공제사·손해보험사·브로커·손해사정·학계 (현장 7명 + 서면 2~3명)
A4: 시작 시각 | C4: 14:00 | D4: ← 실제 시작이 늦어지면 이 셀만 수정 (전체 시각 자동 재계산)
A5: 도입 브리핑 | C5: 사업명 변경 안내 + 재단 서비스 특장점 3가지 슬라이드(약 5분) → 직후 G3-11·12 평가지 작성·회수
A6: 송출 자료 | C6: 특장점 3가지 슬라이드 · 법령 안내 슬라이드 · 법령 슬라이드: https://docs.google.com/presentation/d/1qNKAob6CdE12D9baQVkZxUtktVQAWlEgfi2QJ_5gaso/edit
A8: No. | B8: 시작 | C8: 종료 | D8: 소요(분) | E8: 파트 | F8: 구분 | G8: 진행 내용 (모더레이터 멘트 · 질문 원문) | H8: 송출 · 자료 | I8: 담당 | J8: 스탭 액션 (모니터링룸 · 등록 · 기술) | K8: 실제 시각 · 기록
A9: 1 | B9: =$C$4-180/1440 -> 0.45833333 | D9: T-180분 | E9: 당일 준비 | F9: 참석 확인 | G9: 참석 확인 전화 2차 — 불참 발생 시 대체 Pool에서 즉시 충원, 좌석·명패 재조정 | I9: 등록관리
A10: 2 | B10: =$C$4-90/1440 -> 0.52083333 | D10: T-90분 | E10: 당일 준비 | F10: 집결 | G10: 스탭 현장 집결·입실 (대관 장소는 예약 시작 시각 확인). 비상구·소화기·대피로 확인 | I10: 전원 · 기술
A11: 3 | B11: =$C$4-80/1440 -> 0.52777778 | D11: T-80분 | E11: 당일 준비 | F11: 현장 미팅 | G11: 역할·동선·비상 연락처·오늘 회차 특이사항(참석 인원, 서면 참여자, 참관자) 공유 | I11: PM
A12: 4 | B12: =$C$4-60/1440 -> 0.54166667 | D12: T-60분 | E12: 당일 준비 | F12: 세팅 | G12: 인터뷰룸 좌석(원형·ㄷ자)·탁상 명패(P번호)·좌석배치표 배치 / 음료·종이컵·냅킨(여분 10%) / 모니터링룸 책상·의자·좌석별 전원 | I12: 등록관리
A13: 5 | B13: =$C$4-45/1440 -> 0.55208333 | D13: T-45분 | E13: 당일 준비 | F13: 기술 | G13: 줌 카메라 3대 연결, 모니터링룸 화면·음향 확인 / 두 방 인터넷 속도 확인(끊기면 테더링) / 노트북별 전원·인터넷·현장 기록 문서 접속 / Plaud 2대 충전·녹음 대기 | I13: 기술
A14: 6 | B14: =$C$4-30/1440 -> 0.5625 | D14: T-30분 | E14: 당일 준비 | F14: 송출 준비 | G14: 송출 자료 순서대로 탭 열기 · 현장 기록 문서를 모더레이터 노트북에 열람 상태로 · 현장 리허설 1회전(송출 전환, 모니터링룸 화면·음향) | I14: 기술
A15: 7 | B15: =$C$4-20/1440 -> 0.56944444 | D15: T-20분 | E15: 당일 준비 | F15: 리마인드 | G15: 모더레이터 리마인드 — 첫 5분 진행 순서와 송출 시점 재확인. 참관자 착석·개인정보 원칙(번호 사용·촬영 금지) 안내 | I15: PM · 오거나이저
A16: 8 | B16: =$C$4-10/1440 -> 0.57638889 | D16: T-10분 | E16: 당일 준비 | F16: 등록 | G16: 등록 개시 — 인적 사항 확인, 명패 배부·좌석 안내, 녹음·녹화 동의서 서명, 사전 서면 평가지 배부·회수, 답례 지급 정보 서류 수령 | I16: 등록관리
A17: 9 | B17: =$C$4 -> 14:00 | D17: T=0 | E17: 당일 준비 | F17: 시작 | G17: 녹화·녹음 개시 — 줌 녹화 + Plaud 2대, 2인 육안 확인. 지각자는 시작 후 10분까지 입장 허용 | I17: 기술 · 등록관리
A18: 10 | B18: =$C$4 -> 14:00 | C18: =B18+D18/1440 -> 0.59027778 | D18: 10 | E18: 도입 | F18: 파트 | G18: ▶ 도입 (10분) | J18: 스크립터: 실제 시작 시각 기입 · 오거나이저: 예정 종료 5분 전 모더레이터에 시그널
A19: 11 | F19: 안내 | G19: 인사 — 오늘 참석해 주셔서 감사합니다. 지금부터 스포츠안전재단 손해구제 서비스 집단심층면접을 시작하겠습니다. | I19: 모더레이터
A20: 12 | F20: 소개 | G20: 모더레이터 소개 — 진행을 맡은 (소속·성명)입니다. 오늘은 정답을 찾는 자리가 아니라 여러분의 경험과 의견을 듣는 자리입니다. | I20: 모더레이터
A21: 13 | F21: 소개 | G21: 조사기관 소개 — 이 조사는 재단과 별개의 제3기관인 코리아스픽스가 수행합니다. | I21: 모더레이터
A22: 14 | F22: 확인 | G22: 참석자 확인 — 명패의 응답자 번호를 확인해 주십시오. 오늘은 성명 대신 번호로 부르겠습니다. | H22: 탁상 명패(P번호) | I22: 모더레이터 | J22: 등록관리: 미서명자 즉시 확인
A23: 15 | F23: 확인 | G23: 녹화·녹음 동의서 서명과 사전 서면 평가지 회수 여부를 확인한다. | H23: 동의서 · 사전 서면 평가지 | I23: 등록관리 | J23: 등록관리: 미서명자 즉시 확인
A24: 16 | F24: 안내 | G24: 진행 안내 — 120분간 쉬는 시간 없이 진행합니다. 화장실은 필요하실 때 다녀오셔도 됩니다. | I24: 모더레이터
A25: 17 | F25: 안내 | G25: 비밀보장 — 발언은 분석 목적으로만 쓰며 보고서에는 성명 없이 인용됩니다. 답변을 원하지 않으시면 넘어가셔도 됩니다. 중도 퇴장도 가능합니다. | I25: 모더레이터
A26: 18 | F26: 안내 | G26: 발언 규칙 — 서로 다른 의견이 그대로 나오는 것이 좋습니다. 한 분씩 말씀해 주시고 다른 분 의견을 반박하지 않으셔도 됩니다. | I26: 모더레이터
A27: 19 | F27: 소개 | G27: 참석자 자기소개 — 번호 순서로 소속과 재단 서비스 이용 경험을 한 줄씩 말씀해 주십시오. | I27: 모더레이터
A28: 20 | F28: 안내 | G28: 사업명 변경 안내 — 재단 사업명이 기존 ‘공제 서비스’에서 ‘손해구제 서비스’로 변경되었습니다. 기존 ‘스포츠안전공제’가 보험 중심의 다소 한정적인 의미였다면, ‘손해구제 서비스’는 스포츠 활동 중 사고 발생 전·중·후 체육인에게 발생할 수 있는 다양한 손해를 폭넓게 구제한다는 의미입니다. 기존 공제보험도 손해구제 서비스에 포함되며, 오늘 논의의 주요 대상은 기존 공제보험입니다. | I28: 모더레이터
A29: 21 | F29: 송출 | G29: 재단 서비스 특장점 브리핑(약 5분) — ① 종목·연령·장애 여부·병력 유무 등에 따른 가입 거절 없음 ② 개인 실손보험 등과 중복 보상 가능(배상책임·실비 담보는 비례보상) ③ 생활체육인·전문체육인 전용·특화 담보 운영(주최 측 과실이 없는 운동 중 부상 치료비, 배상책임 등) | H29: 특장점 3가지 슬라이드 | I29: 모더레이터 | J29: 기술: 인터뷰룸 모니터 전환
A30: 22 | F30: 평가지 | G30: 특장점 브리핑 직후 G3-11·12 평가지 작성·회수 (브리핑 전 작성한 응답은 수정하지 않음) | H30: 서면 평가지 G3-11·12 | I30: 등록관리 | J30: 등록관리: 배부·회수 후 봉투 보관
A31: 23 | B31: =B18+D18/1440 -> 0.59027778 | C31: =B31+D31/1440 -> 0.60763889 | D31: 25 | E31: 시장 포지셔닝 진단 | F31: 파트 | G31: ▶ 시장 포지셔닝 진단 (25분) | J31: 스크립터: 실제 시작 시각 기입 · 오거나이저: 예정 종료 5분 전 모더레이터에 시그널
A32: 24 | F32: 질문 | G32: 스포츠 상해·배상 공제 시장에서 재단 서비스의 현재 포지션에 가장 가까운 것은 무엇입니까? ① 민간이 못 하는 영역을 메우는 공공 보완재 ② 민간과 직접 경쟁하는 경쟁재 ③ 특정 수요층 대상 틈새 상품 ④ 기타 | I32: 모더레이터
A33: 25 | F33: 거수 | G33: 〔현재 포지션〕 ① 공공 보완재 ② 경쟁재 ③ 틈새 ④ 기타 → 인원 | I33: 오거나이저 | J33: 오거나이저: 인원 수 기록 → 스크립터 공유
A34: 26 | F34: 질문 | G34: 그렇게 진단한 근거는 무엇입니까? | I34: 모더레이터
A35: 27 | F35: 질문 | G35: 민간 손해보험사 상품(삼성화재·DB·캐롯 등)과 비교했을 때 재단 상품의 강점과 약점은 무엇입니까? | I35: 모더레이터
A36: 28 | F36: 질문 | G36: 민간 보험사가 인수를 꺼리는 종목·대상·조건의 실태는 어떻습니까? 그 영역에서 재단의 역할을 어떻게 보십니까? | I36: 모더레이터
A37: 29 | B37: =B31+D31/1440 -> 0.60763889 | C37: =B37+D37/1440 -> 0.61805556 | D37: 15 | E37: 차별성 검증 | F37: 파트 | G37: ▶ 차별성 검증 (15분) | J37: 스크립터: 실제 시작 시각 기입 · 오거나이저: 예정 종료 5분 전 모더레이터에 시그널
A38: 30 | F38: 질문 | G38: 종목·연령·장애·병력 유무 등에 따른 가입 거절이 없다는 재단의 특성은 시장에서 어느 정도 경쟁력이라고 보십니까? (실질적 경쟁력이다 / 제한적이다 / 경쟁력이 아니다) | I38: 모더레이터
A39: 31 | F39: 거수 | G39: 〔가입 거절 없음의 경쟁력〕 ① 아니다 ② 제한적 ③ 실질적 → 인원 | I39: 오거나이저 | J39: 오거나이저: 인원 수 기록 → 스크립터 공유
A40: 32 | F40: 질문 | G40: 그렇게 판단한 이유는 무엇입니까? | I40: 모더레이터
A41: 33 | F41: 질문 | G41: 이 특성이 앞으로도 유지 가능하다고 보십니까? 지속가능성을 위협하는 요인은 무엇입니까? | I41: 모더레이터
...

Sheet G4_큐시트
A1: [그룹 4 · 재단 내부 관계자] 스포츠안전재단 손해구제 서비스 FGI 큐시트
A2: 2026-09-17(목) · 스포츠안전재단 교육장 (서울 송파구 올림픽로 424, 올림픽공원 테니스경기장 3층)
A3: 대상: 재단 임직원 — 보임자 4명, 실무자 4명 (안전공제실 등 관련 부서, 개인 명단 미정)
A4: 시작 시각 | C4: 14:00 | D4: ← 실제 시작이 늦어지면 이 셀만 수정 (전체 시각 자동 재계산)
A5: 도입 브리핑 | C5: 사업명 변경 안내만 (특장점 브리핑 없음)
A6: 송출 자료 | C6: 법령 안내 슬라이드 · Top 3 개인 작성 용지 · 법령 슬라이드: https://docs.google.com/presentation/d/1qNKAob6CdE12D9baQVkZxUtktVQAWlEgfi2QJ_5gaso/edit
A8: No. | B8: 시작 | C8: 종료 | D8: 소요(분) | E8: 파트 | F8: 구분 | G8: 진행 내용 (모더레이터 멘트 · 질문 원문) | H8: 송출 · 자료 | I8: 담당 | J8: 스탭 액션 (모니터링룸 · 등록 · 기술) | K8: 실제 시각 · 기록
A9: 1 | B9: =$C$4-180/1440 -> 0.45833333 | D9: T-180분 | E9: 당일 준비 | F9: 참석 확인 | G9: 참석 확인 전화 2차 — 불참 발생 시 대체 Pool에서 즉시 충원, 좌석·명패 재조정 | I9: 등록관리
A10: 2 | B10: =$C$4-90/1440 -> 0.52083333 | D10: T-90분 | E10: 당일 준비 | F10: 집결 | G10: 스탭 현장 집결·입실 (대관 장소는 예약 시작 시각 확인). 비상구·소화기·대피로 확인 | I10: 전원 · 기술
A11: 3 | B11: =$C$4-80/1440 -> 0.52777778 | D11: T-80분 | E11: 당일 준비 | F11: 현장 미팅 | G11: 역할·동선·비상 연락처·오늘 회차 특이사항(참석 인원, 서면 참여자, 참관자) 공유 | I11: PM
A12: 4 | B12: =$C$4-60/1440 -> 0.54166667 | D12: T-60분 | E12: 당일 준비 | F12: 세팅 | G12: 인터뷰룸 좌석(원형·ㄷ자)·탁상 명패(P번호)·좌석배치표 배치 / 음료·종이컵·냅킨(여분 10%) / 모니터링룸 책상·의자·좌석별 전원 | I12: 등록관리
A13: 5 | B13: =$C$4-45/1440 -> 0.55208333 | D13: T-45분 | E13: 당일 준비 | F13: 기술 | G13: 줌 카메라 3대 연결, 모니터링룸 화면·음향 확인 / 두 방 인터넷 속도 확인(끊기면 테더링) / 노트북별 전원·인터넷·현장 기록 문서 접속 / Plaud 2대 충전·녹음 대기 | I13: 기술
A14: 6 | B14: =$C$4-30/1440 -> 0.5625 | D14: T-30분 | E14: 당일 준비 | F14: 송출 준비 | G14: 송출 자료 순서대로 탭 열기 · 현장 기록 문서를 모더레이터 노트북에 열람 상태로 · 현장 리허설 1회전(송출 전환, 모니터링룸 화면·음향) | I14: 기술
A15: 7 | B15: =$C$4-20/1440 -> 0.56944444 | D15: T-20분 | E15: 당일 준비 | F15: 리마인드 | G15: 모더레이터 리마인드 — 첫 5분 진행 순서와 송출 시점 재확인. 참관자 착석·개인정보 원칙(번호 사용·촬영 금지) 안내 | I15: PM · 오거나이저
A16: 8 | B16: =$C$4-10/1440 -> 0.57638889 | D16: T-10분 | E16: 당일 준비 | F16: 등록 | G16: 등록 개시 — 인적 사항 확인, 명패 배부·좌석 안내, 녹음·녹화 동의서 서명, 사전 서면 평가지 배부·회수, 답례 지급 정보 서류 수령 | I16: 등록관리
A17: 9 | B17: =$C$4 -> 14:00 | D17: T=0 | E17: 당일 준비 | F17: 시작 | G17: 녹화·녹음 개시 — 줌 녹화 + Plaud 2대, 2인 육안 확인. 지각자는 시작 후 10분까지 입장 허용 | I17: 기술 · 등록관리
A18: 10 | B18: =$C$4 -> 14:00 | C18: =B18+D18/1440 -> 0.59027778 | D18: 10 | E18: 도입 | F18: 파트 | G18: ▶ 도입 (10분) | J18: 스크립터: 실제 시작 시각 기입 · 오거나이저: 예정 종료 5분 전 모더레이터에 시그널
A19: 11 | F19: 안내 | G19: 인사 — 오늘 참석해 주셔서 감사합니다. 지금부터 스포츠안전재단 손해구제 서비스 집단심층면접을 시작하겠습니다. | I19: 모더레이터
A20: 12 | F20: 소개 | G20: 모더레이터 소개 — 진행을 맡은 (소속·성명)입니다. 오늘은 정답을 찾는 자리가 아니라 여러분의 경험과 의견을 듣는 자리입니다. | I20: 모더레이터
A21: 13 | F21: 소개 | G21: 조사기관 소개 — 이 조사는 재단과 별개의 제3기관인 코리아스픽스가 수행합니다. | I21: 모더레이터
A22: 14 | F22: 확인 | G22: 참석자 확인 — 명패의 응답자 번호를 확인해 주십시오. 오늘은 성명 대신 번호로 부르겠습니다. | H22: 탁상 명패(P번호) | I22: 모더레이터 | J22: 등록관리: 미서명자 즉시 확인
A23: 15 | F23: 확인 | G23: 녹화·녹음 동의서 서명과 사전 서면 평가지 회수 여부를 확인한다. | H23: 동의서 · 사전 서면 평가지 | I23: 등록관리 | J23: 등록관리: 미서명자 즉시 확인
A24: 16 | F24: 안내 | G24: 진행 안내 — 120분간 쉬는 시간 없이 진행합니다. 화장실은 필요하실 때 다녀오셔도 됩니다. | I24: 모더레이터
A25: 17 | F25: 안내 | G25: 비밀보장 — 발언은 분석 목적으로만 쓰며 보고서에는 성명 없이 인용됩니다. 답변을 원하지 않으시면 넘어가셔도 됩니다. 중도 퇴장도 가능합니다. | I25: 모더레이터
A26: 18 | F26: 안내 | G26: 발언 규칙 — 서로 다른 의견이 그대로 나오는 것이 좋습니다. 한 분씩 말씀해 주시고 다른 분 의견을 반박하지 않으셔도 됩니다. | I26: 모더레이터
A27: 19 | F27: 소개 | G27: 참석자 자기소개 — 번호 순서로 소속과 재단 서비스 이용 경험을 한 줄씩 말씀해 주십시오. | I27: 모더레이터
A28: 20 | F28: 안내 | G28: 사업명 변경 안내 — 재단 사업명이 기존 ‘공제 서비스’에서 ‘손해구제 서비스’로 변경되었습니다. 기존 ‘스포츠안전공제’가 보험 중심의 다소 한정적인 의미였다면, ‘손해구제 서비스’는 스포츠 활동 중 사고 발생 전·중·후 체육인에게 발생할 수 있는 다양한 손해를 폭넓게 구제한다는 의미입니다. 기존 공제보험도 손해구제 서비스에 포함되며, 오늘 논의의 주요 대상은 기존 공제보험입니다. | I28: 모더레이터
A29: 21 | B29: =B18+D18/1440 -> 0.59027778 | C29: =B29+D29/1440 -> 0.60416667 | D29: 20 | E29: 운영 현황 | F29: 파트 | G29: ▶ 운영 현황 (20분) | J29: 스크립터: 실제 시작 시각 기입 · 오거나이저: 예정 종료 5분 전 모더레이터에 시그널
A30: 22 | F30: 질문 | G30: 부서별 업무 프로세스에서 손해구제 서비스는 어떻게 운영되고 있습니까? | I30: 모더레이터
A31: 23 | F31: 질문 | G31: 현장에서 가장 많이 접수되는 민원·문의 유형은 무엇이고, 어떤 과정으로 처리됩니까? | I31: 모더레이터
A32: 24 | F32: 거수 | G32: 〔다빈도 민원 (2개)〕 ① 가입대상 ② 가입증빙 ③ 보상한도 ④ 상품선택 ⑤ 보상·면책 ⑥ 기타 → 인원 | I32: 오거나이저 | J32: 오거나이저: 인원 수 기록 → 스크립터 공유
A33: 25 | B33: =B29+D29/1440 -> 0.60416667 | C33: =B33+D33/1440 -> 0.61458333 | D33: 15 | E33: 내부 인식 | F33: 파트 | G33: ▶ 내부 인식 (15분) | J33: 스크립터: 실제 시작 시각 기입 · 오거나이저: 예정 종료 5분 전 모더레이터에 시그널
A34: 26 | F34: 질문 | G34: 외부 고객 만족도와 내부 자체평가 사이에 온도차가 있다고 느끼십니까? (크다 / 다소 있다 / 거의 없다) | I34: 모더레이터
A35: 27 | F35: 거수 | G35: 〔온도차〕 ① 거의 없다 ② 다소 있다 ③ 크다 → 인원 | I35: 오거나이저 | J35: 오거나이저: 인원 수 기록 → 스크립터 공유
A36: 28 | F36: 질문 | G36: 어떤 지점에서 그렇게 느끼십니까? | I36: 모더레이터
A37: 29 | F37: 질문 | G37: 고객이 모르는, 내부만 아는 서비스의 강점·약점이 있다면 무엇입니까? | I37: 모더레이터
A38: 30 | B38: =B33+D33/1440 -> 0.61458333 | C38: =B38+D38/1440 -> 0.62152778 | D38: 10 | E38: 법·제도 인식 | F38: 파트 | G38: ▶ 법·제도 인식 (10분) | J38: 스크립터: 실제 시작 시각 기입 · 오거나이저: 예정 종료 5분 전 모더레이터에 시그널
A39: 31 | F39: 질문 | G39: 재난안전의무보험 제도와 ‘대인 1억 5천만 원 이상’ 기준을 업무에서 다뤄본 적이 있습니까? ① 업무로 직접 다룬다 ② 알지만 내 업무와 무관하다 ③ 잘 모른다 | I39: 모더레이터
A40: 32 | F40: 거수 | G40: 〔의무보험 제도 인지〕 ① 직접 다룬다 ② 알지만 무관 ③ 잘 모른다 → 인원 | I40: 오거나이저 | J40: 오거나이저: 인원 수 기록 → 스크립터 공유
A41: 33 | F41: 송출 | G41: 인터뷰룸 모니터에 법령 안내 슬라이드 6장을 띄운다. 인지 확인(거수) → 슬라이드 송출 → 경험·의견 청취 순. 사실 전달에 한정하고 법령 해석 요구 시 재단 고객상담(1899-0547) 안내. | H41: 법령 안내 슬라이드 (https://docs.google.com/presentation/d/1qNKAob6CdE12D9baQVkZxUtktVQAWlEgfi2QJ_5gaso/edit) | I41: 기술 | J41: 기술: 인터뷰룸 모니터 전환
...

Sheet 공유용_요약
A1: 스포츠안전재단 손해구제 서비스 FGI 진행 시간표 (공유용)
A2: 주관: 코리아스픽스 · 회당 120분 · 도입 10분 → 인터뷰 100분 → 마무리 10분. 시각은 각 회차 큐시트의 시작 시각과 연동된다.
A4: 그룹 1 · 사업 이용 고객 · 2026-09-07(월) · 패스트파이브 서울역점 (서울 용산구 동자동 56 트윈시티 남산2)
A5: 회차 | B5: 시작 | C5: 종료 | D5: 소요(분) | E5: 파트 | F5: 송출 · 안내
A6: 그룹 1 · 사업 이용 고객 | B6: =G1_큐시트!B18 -> 14:00 | C6: =G1_큐시트!C18 -> 0.59027778 | D6: =G1_큐시트!D18 -> 10 | E6: 도입 | F6: 사업명 변경 안내
A7: 그룹 1 · 사업 이용 고객 | B7: =G1_큐시트!B29 -> 0.59027778 | C7: =G1_큐시트!C29 -> 0.59722222 | D7: =G1_큐시트!D29 -> 10 | E7: 인지·가입 경로
A8: 그룹 1 · 사업 이용 고객 | B8: =G1_큐시트!B34 -> 0.59722222 | C8: =G1_큐시트!C34 -> 0.60763889 | D8: =G1_큐시트!D34 -> 15 | E8: 가입 절차 (정량 A 연동) | F8: 재단 홈페이지 가입 화면 · AI 상담 화면
A9: 그룹 1 · 사업 이용 고객 | B9: =G1_큐시트!B42 -> 0.60763889 | C9: =G1_큐시트!C42 -> 0.61458333 | D9: =G1_큐시트!D42 -> 10 | E9: 콜센터·고객센터 (정량 B 연동)
A10: 그룹 1 · 사업 이용 고객 | B10: =G1_큐시트!B47 -> 0.61458333 | C10: =G1_큐시트!C47 -> 0.62152778 | D10: =G1_큐시트!D47 -> 10 | E10: 상품 정보 이해 (정량 C 연동)
A11: 그룹 1 · 사업 이용 고객 | B11: =G1_큐시트!B52 -> 0.62152778 | C11: =G1_큐시트!C52 -> 0.63194444 | D11: =G1_큐시트!D52 -> 15 | E11: 상품·회비 (정량 D 연동)
A12: 그룹 1 · 사업 이용 고객 | B12: =G1_큐시트!B58 -> 0.63194444 | C12: =G1_큐시트!C58 -> 0.64583333 | D12: =G1_큐시트!D58 -> 20 | E12: 보험금 청구 (정량 E 연동 · 청구 경험자 중심)
A13: 그룹 1 · 사업 이용 고객 | B13: =G1_큐시트!B67 -> 0.64583333 | C13: =G1_큐시트!C67 -> 0.65277778 | D13: =G1_큐시트!D67 -> 10 | E13: 법·제도 인식 | F13: 법령 안내 슬라이드
A14: 그룹 1 · 사업 이용 고객 | B14: =G1_큐시트!B77 -> 0.65277778 | C14: =G1_큐시트!C77 -> 0.65972222 | D14: =G1_큐시트!D77 -> 10 | E14: 종합·NPS·신규 수요
A15: 그룹 1 · 사업 이용 고객 | B15: =G1_큐시트!B87 -> 0.65972222 | C15: =G1_큐시트!C87 -> 0.66666667 | D15: =G1_큐시트!D87 -> 10 | E15: 마무리
A17: 그룹 2 · 사업협력 단체 · 2026-09-08(화) · 스포츠안전재단 교육장 (서울 송파구 올림픽로 424, 올림픽공원 테니스경기장 3층)
A18: 회차 | B18: 시작 | C18: 종료 | D18: 소요(분) | E18: 파트 | F18: 송출 · 안내
A19: 그룹 2 · 사업협력 단체 | B19: =G2_큐시트!B18 -> 14:00 | C19: =G2_큐시트!C18 -> 0.59027778 | D19: =G2_큐시트!D18 -> 10 | E19: 도입 | F19: 사업명 변경 안내 · 특장점 3가지 슬라이드 · 서면 평가지 작성
A20: 그룹 2 · 사업협력 단체 | B20: =G2_큐시트!B31 -> 0.59027778 | C20: =G2_큐시트!C31 -> 0.60416667 | D20: =G2_큐시트!D31 -> 20 | E20: 협업 경험
A21: 그룹 2 · 사업협력 단체 | B21: =G2_큐시트!B38 -> 0.60416667 | C21: =G2_큐시트!C38 -> 0.61805556 | D21: =G2_큐시트!D38 -> 20 | E21: 제도 연계 | F21: 법령 안내 슬라이드
A22: 그룹 2 · 사업협력 단체 | B22: =G2_큐시트!B49 -> 0.61805556 | C22: =G2_큐시트!C49 -> 0.63194444 | D22: =G2_큐시트!D49 -> 20 | E22: 회원·산하단체 안내
A23: 그룹 2 · 사업협력 단체 | B23: =G2_큐시트!B55 -> 0.63194444 | C23: =G2_큐시트!C55 -> 0.64236111 | D23: =G2_큐시트!D55 -> 15 | E23: 정책적 역할
A24: 그룹 2 · 사업협력 단체 | B24: =G2_큐시트!B59 -> 0.64236111 | C24: =G2_큐시트!C59 -> 0.65277778 | D24: =G2_큐시트!D59 -> 15 | E24: 개선 제안·협력 확대
A25: 그룹 2 · 사업협력 단체 | B25: =G2_큐시트!B66 -> 0.65277778 | C25: =G2_큐시트!C66 -> 0.65972222 | D25: =G2_큐시트!D66 -> 10 | E25: 예비
A26: 그룹 2 · 사업협력 단체 | B26: =G2_큐시트!B68 -> 0.65972222 | C26: =G2_큐시트!C68 -> 0.66666667 | D26: =G2_큐시트!D68 -> 10 | E26: 마무리
A28: 그룹 3 · 손해구제 전문가 · 2026-09-15(화) · 패스트파이브 삼성1호점 (서울 강남구 테헤란로87길 36 City Airport Tower 24층)
A29: 회차 | B29: 시작 | C29: 종료 | D29: 소요(분) | E29: 파트 | F29: 송출 · 안내
A30: 그룹 3 · 손해구제 전문가 | B30: =G3_큐시트!B18 -> 14:00 | C30: =G3_큐시트!C18 -> 0.59027778 | D30: =G3_큐시트!D18 -> 10 | E30: 도입 | F30: 사업명 변경 안내 · 특장점 3가지 슬라이드 · 서면 평가지 작성
A31: 그룹 3 · 손해구제 전문가 | B31: =G3_큐시트!B31 -> 0.59027778 | C31: =G3_큐시트!C31 -> 0.60763889 | D31: =G3_큐시트!D31 -> 25 | E31: 시장 포지셔닝 진단
A32: 그룹 3 · 손해구제 전문가 | B32: =G3_큐시트!B37 -> 0.60763889 | C32: =G3_큐시트!C37 -> 0.61805556 | D32: =G3_큐시트!D37 -> 15 | E32: 차별성 검증
A33: 그룹 3 · 손해구제 전문가 | B33: =G3_큐시트!B42 -> 0.61805556 | C33: =G3_큐시트!C42 -> 0.62847222 | D33: =G3_큐시트!D42 -> 15 | E33: 리스크 진단
A34: 그룹 3 · 손해구제 전문가 | B34: =G3_큐시트!B45 -> 0.62847222 | C34: =G3_큐시트!C45 -> 0.63888889 | D34: =G3_큐시트!D45 -> 15 | E34: 청구 프로세스 평가
A35: 그룹 3 · 손해구제 전문가 | B35: =G3_큐시트!B50 -> 0.63888889 | C35: =G3_큐시트!C50 -> 0.64583333 | D35: =G3_큐시트!D50 -> 10 | E35: 법·제도 인식 | F35: 법령 안내 슬라이드
A36: 그룹 3 · 손해구제 전문가 | B36: =G3_큐시트!B57 -> 0.64583333 | C36: =G3_큐시트!C57 -> 0.65972222 | D36: =G3_큐시트!D57 -> 20 | E36: 개선·발전 방향
A37: 그룹 3 · 손해구제 전문가 | B37: =G3_큐시트!B66 -> 0.65972222 | C37: =G3_큐시트!C66 -> 0.66666667 | D37: =G3_큐시트!D66 -> 10 | E37: 마무리
A39: 그룹 4 · 재단 내부 관계자 · 2026-09-17(목) · 스포츠안전재단 교육장 (서울 송파구 올림픽로 424, 올림픽공원 테니스경기장 3층)
A40: 회차 | B40: 시작 | C40: 종료 | D40: 소요(분) | E40: 파트 | F40: 송출 · 안내
A41: 그룹 4 · 재단 내부 관계자 | B41: =G4_큐시트!B18 -> 14:00 | C41: =G4_큐시트!C18 -> 0.59027778 | D41: =G4_큐시트!D18 -> 10 | E41: 도입 | F41: 사업명 변경 안내
A42: 그룹 4 · 재단 내부 관계자 | B42: =G4_큐시트!B29 -> 0.59027778 | C42: =G4_큐시트!C29 -> 0.60416667 | D42: =G4_큐시트!D29 -> 20 | E42: 운영 현황
A43: 그룹 4 · 재단 내부 관계자 | B43: =G4_큐시트!B33 -> 0.60416667 | C43: =G4_큐시트!C33 -> 0.61458333 | D43: =G4_큐시트!D33 -> 15 | E43: 내부 인식
A44: 그룹 4 · 재단 내부 관계자 | B44: =G4_큐시트!B38 -> 0.61458333 | C44: =G4_큐시트!C38 -> 0.62152778 | D44: =G4_큐시트!D38 -> 10 | E44: 법·제도 인식 | F44: 법령 안내 슬라이드
...
